==== TEST RUN LOG ====
Test Name      : diamondgotcat.ypsh
Test File      : D:\a\testing-system\testing-system\tests\diamondgotcat.ypsh.py
Command        : C:\hostedtoolcache\windows\Python\3.12.10\x64\python.exe D:\a\testing-system\testing-system\tests\diamondgotcat.ypsh.py
Start (UTC)    : 2025-09-22T12:05:34.108007+00:00
Epoch (ns)     : 1758542734076755500
---- ENVIRONMENT ----
python_executable: C:\hostedtoolcache\windows\Python\3.12.10\x64\python.exe
python_version   : 3.12.10 (tags/v3.12.10:0cc8128, Apr  8 2025, 12:21:36) [MSC v.1943 64 bit (AMD64)]
platform         : Windows-2022Server-10.0.20348-SP0
cwd              : D:\a\testing-system\testing-system
tests_dir        : D:\a\testing-system\testing-system\tests
os               : windows
arch             : amd64
----------------------
---- STDOUT ----

---- STDERR ----
D:\a\testing-system\testing-system\tests\diamondgotcat.ypsh.py:108: SyntaxWarning: invalid escape sequence '\('
  print("Hello, \(name)!")
Traceback (most recent call last):
  File "C:\hostedtoolcache\windows\Python\3.12.10\x64\Lib\site-packages\urllib3\connectionpool.py", line 787, in urlopen
    response = self._make_request(
               ^^^^^^^^^^^^^^^^^^^
  File "C:\hostedtoolcache\windows\Python\3.12.10\x64\Lib\site-packages\urllib3\connectionpool.py", line 488, in _make_request
    raise new_e
  File "C:\hostedtoolcache\windows\Python\3.12.10\x64\Lib\site-packages\urllib3\connectionpool.py", line 464, in _make_request
    self._validate_conn(conn)
  File "C:\hostedtoolcache\windows\Python\3.12.10\x64\Lib\site-packages\urllib3\connectionpool.py", line 1093, in _validate_conn
    conn.connect()
  File "C:\hostedtoolcache\windows\Python\3.12.10\x64\Lib\site-packages\urllib3\connection.py", line 790, in connect
    sock_and_verified = _ssl_wrap_socket_and_match_hostname(
                        ^^^^^^^^^^^^^^^^^^^^^^^^^^^^^^^^^^^^
  File "C:\hostedtoolcache\windows\Python\3.12.10\x64\Lib\site-packages\urllib3\connection.py", line 969, in _ssl_wrap_socket_and_match_hostname
    ssl_sock = ssl_wrap_socket(
               ^^^^^^^^^^^^^^^^
  File "C:\hostedtoolcache\windows\Python\3.12.10\x64\Lib\site-packages\urllib3\util\ssl_.py", line 480, in ssl_wrap_socket
    ssl_sock = _ssl_wrap_socket_impl(sock, context, tls_in_tls, server_hostname)
               ^^^^^^^^^^^^^^^^^^^^^^^^^^^^^^^^^^^^^^^^^^^^^^^^^^^^^^^^^^^^^^^^^
  File "C:\hostedtoolcache\windows\Python\3.12.10\x64\Lib\site-packages\urllib3\util\ssl_.py", line 524, in _ssl_wrap_socket_impl
    return ssl_context.wrap_socket(sock, server_hostname=server_hostname)
           ^^^^^^^^^^^^^^^^^^^^^^^^^^^^^^^^^^^^^^^^^^^^^^^^^^^^^^^^^^^^^^
  File "C:\hostedtoolcache\windows\Python\3.12.10\x64\Lib\ssl.py", line 455, in wrap_socket
    return self.sslsocket_class._create(
           ^^^^^^^^^^^^^^^^^^^^^^^^^^^^^
  File "C:\hostedtoolcache\windows\Python\3.12.10\x64\Lib\ssl.py", line 1041, in _create
    self.do_handshake()
  File "C:\hostedtoolcache\windows\Python\3.12.10\x64\Lib\ssl.py", line 1319, in do_handshake
    self._sslobj.do_handshake()
ConnectionResetError: [WinError 10054] An existing connection was forcibly closed by the remote host

During handling of the above exception, another exception occurred:

Traceback (most recent call last):
  File "C:\hostedtoolcache\windows\Python\3.12.10\x64\Lib\site-packages\requests\adapters.py", line 644, in send
    resp = conn.urlopen(
           ^^^^^^^^^^^^^
  File "C:\hostedtoolcache\windows\Python\3.12.10\x64\Lib\site-packages\urllib3\connectionpool.py", line 841, in urlopen
    retries = retries.increment(
              ^^^^^^^^^^^^^^^^^^
  File "C:\hostedtoolcache\windows\Python\3.12.10\x64\Lib\site-packages\urllib3\util\retry.py", line 474, in increment
    raise reraise(type(error), error, _stacktrace)
          ^^^^^^^^^^^^^^^^^^^^^^^^^^^^^^^^^^^^^^^^
  File "C:\hostedtoolcache\windows\Python\3.12.10\x64\Lib\site-packages\urllib3\util\util.py", line 38, in reraise
    raise value.with_traceback(tb)
  File "C:\hostedtoolcache\windows\Python\3.12.10\x64\Lib\site-packages\urllib3\connectionpool.py", line 787, in urlopen
    response = self._make_request(
               ^^^^^^^^^^^^^^^^^^^
  File "C:\hostedtoolcache\windows\Python\3.12.10\x64\Lib\site-packages\urllib3\connectionpool.py", line 488, in _make_request
    raise new_e
  File "C:\hostedtoolcache\windows\Python\3.12.10\x64\Lib\site-packages\urllib3\connectionpool.py", line 464, in _make_request
    self._validate_conn(conn)
  File "C:\hostedtoolcache\windows\Python\3.12.10\x64\Lib\site-packages\urllib3\connectionpool.py", line 1093, in _validate_conn
    conn.connect()
  File "C:\hostedtoolcache\windows\Python\3.12.10\x64\Lib\site-packages\urllib3\connection.py", line 790, in connect
    sock_and_verified = _ssl_wrap_socket_and_match_hostname(
                        ^^^^^^^^^^^^^^^^^^^^^^^^^^^^^^^^^^^^
  File "C:\hostedtoolcache\windows\Python\3.12.10\x64\Lib\site-packages\urllib3\connection.py", line 969, in _ssl_wrap_socket_and_match_hostname
    ssl_sock = ssl_wrap_socket(
               ^^^^^^^^^^^^^^^^
  File "C:\hostedtoolcache\windows\Python\3.12.10\x64\Lib\site-packages\urllib3\util\ssl_.py", line 480, in ssl_wrap_socket
    ssl_sock = _ssl_wrap_socket_impl(sock, context, tls_in_tls, server_hostname)
               ^^^^^^^^^^^^^^^^^^^^^^^^^^^^^^^^^^^^^^^^^^^^^^^^^^^^^^^^^^^^^^^^^
  File "C:\hostedtoolcache\windows\Python\3.12.10\x64\Lib\site-packages\urllib3\util\ssl_.py", line 524, in _ssl_wrap_socket_impl
    return ssl_context.wrap_socket(sock, server_hostname=server_hostname)
           ^^^^^^^^^^^^^^^^^^^^^^^^^^^^^^^^^^^^^^^^^^^^^^^^^^^^^^^^^^^^^^
  File "C:\hostedtoolcache\windows\Python\3.12.10\x64\Lib\ssl.py", line 455, in wrap_socket
    return self.sslsocket_class._create(
           ^^^^^^^^^^^^^^^^^^^^^^^^^^^^^
  File "C:\hostedtoolcache\windows\Python\3.12.10\x64\Lib\ssl.py", line 1041, in _create
    self.do_handshake()
  File "C:\hostedtoolcache\windows\Python\3.12.10\x64\Lib\ssl.py", line 1319, in do_handshake
    self._sslobj.do_handshake()
urllib3.exceptions.ProtocolError: ('Connection aborted.', ConnectionResetError(10054, 'An existing connection was forcibly closed by the remote host', None, 10054, None))

During handling of the above exception, another exception occurred:

Traceback (most recent call last):
  File "D:\a\testing-system\testing-system\tests\diamondgotcat.ypsh.py", line 124, in <module>
    main()
  File "D:\a\testing-system\testing-system\tests\diamondgotcat.ypsh.py", line 89, in main
    stableTag = requests.get("https://ypsh-dgc.github.io/YPSH/channels/stable.txt").text.strip()
                ^^^^^^^^^^^^^^^^^^^^^^^^^^^^^^^^^^^^^^^^^^^^^^^^^^^^^^^^^^^^^^^^^^^
  File "C:\hostedtoolcache\windows\Python\3.12.10\x64\Lib\site-packages\requests\api.py", line 73, in get
    return request("get", url, params=params, **kwargs)
           ^^^^^^^^^^^^^^^^^^^^^^^^^^^^^^^^^^^^^^^^^^^^
  File "C:\hostedtoolcache\windows\Python\3.12.10\x64\Lib\site-packages\requests\api.py", line 59, in request
    return session.request(method=method, url=url, **kwargs)
           ^^^^^^^^^^^^^^^^^^^^^^^^^^^^^^^^^^^^^^^^^^^^^^^^^
  File "C:\hostedtoolcache\windows\Python\3.12.10\x64\Lib\site-packages\requests\sessions.py", line 589, in request
    resp = self.send(prep, **send_kwargs)
           ^^^^^^^^^^^^^^^^^^^^^^^^^^^^^^
  File "C:\hostedtoolcache\windows\Python\3.12.10\x64\Lib\site-packages\requests\sessions.py", line 703, in send
    r = adapter.send(request, **kwargs)
        ^^^^^^^^^^^^^^^^^^^^^^^^^^^^^^^
  File "C:\hostedtoolcache\windows\Python\3.12.10\x64\Lib\site-packages\requests\adapters.py", line 659, in send
    raise ConnectionError(err, request=request)
requests.exceptions.ConnectionError: ('Connection aborted.', ConnectionResetError(10054, 'An existing connection was forcibly closed by the remote host', None, 10054, None))
-----------------
End   (UTC)    : 2025-09-22T12:05:34.639259+00:00
Duration (s)   : 0.531252
Return Code    : 1
======================
